Workbook

Sheet Janvier 2018
C1: Suivi objectif réalisation CA par atelier | AG1: 725000
AH3: =22 -> 22
S5: 5188
A7: GRIM PASSION LATTES | B7: 1 | C7: 2 | D7: 3 | E7: 4 | F7: 5 | G7: 6 | H7: 7 | I7: 8 | J7: 9 | K7: 10 | L7: 11 | M7: 12 | N7: 13 | O7: 14 | P7: 15 | Q7: 16 | R7: 17 | S7: 18 | T7: 19 | U7: 20 | V7: 21 | W7: 22 | X7: 23 | Y7: 24 | Z7: 25 | AA7: 26 | AB7: 27 | AC7: 28 | AD7: 29 | AE7: 30 | AF7: 31
A8: CA REALISE (CLIENT CESSION GARANTIE) | C8: 937 | D8: 5142 | E8: 8548 | F8: 12993 | I8: 15791 | J8: 20445 | K8: 27384 | L8: 31560 | M8: 36949.28 | P8: 41396 | Q8: 47051 | R8: 55758 | S8: 64492 | T8: 72736 | W8: 77242 | X8: 83259 | Y8: 89236 | Z8: 92343 | AA8: 99442 | AD8: 102766 | AE8: 108635 | AF8: 116703
A9: OBJECTIF | C9: 5856 | D9: =C9+5856 -> 11712 | E9: =D9+5856 -> 17568 | F9: =E9+5856 -> 23424 | I9: =F9+5856 -> 29280 | J9: =I9+5856 -> 35136 | K9: =J9+5856 -> 40992 | L9: =K9+5856 -> 46848 | M9: =L9+5856 -> 52704 | P9: =M9+5856 -> 58560 | Q9: =P9+5856 -> 64416 | R9: =Q9+5856 -> 70272 | S9: =R9+5856 -> 76128 | T9: =S9+5856 -> 81984 | W9: =T9+5856 -> 87840 | X9: =W9+5856 -> 93696 | Y9: =X9+5856 -> 99552 | Z9: =Y9+5856 -> 105408 | AA9: =Z9+5856 -> 111264 | AD9: =AA9+5856 -> 117120 | AE9: =AD9+5856 -> 122976 | AF9: =AE9+5856 -> 128832
A10: % DE REALISATION | C10: =C8/C9 -> 0.16000683 | D10: =D8/D9 -> 0.43903689 | E10: =E8/E9 -> 0.48656648 | F10: =F8/F9 -> 0.5546875 | I10: =I8/I9 -> 0.53931011 | J10: =J8/J9 -> 0.58188183 | K10: =K8/K9 -> 0.66803279 | L10: =L8/L9 -> 0.67366803 | M10: =M8/M9 -> 0.70107165 | P10: =P8/P9 -> 0.70689891 | Q10: =Q8/Q9 -> 0.73042412 | R10: =R8/R9 -> 0.7934597 | S10: =S8/S9 -> 0.84715216 | T10: =T8/T9 -> 0.8871975 | W10: =W8/W9 -> 0.87934882 | X10: =X8/X9 -> 0.88860784 | Y10: =Y8/Y9 -> 0.89637576 | Z10: =Z8/Z9 -> 0.87605305 | AA10: =AA8/AA9 -> 0.8937482 | AD10: =AD8/AD9 -> 0.87744194 | AE10: =AE8/AE9 -> 0.88338375 | AF10: =AF8/AF9 -> 0.90585414
A14: GRIM PASSION PEROLS | B14: 1 | C14: 2 | D14: 3 | E14: 4 | F14: 5 | G14: 6 | H14: 7 | I14: 8 | J14: 9 | K14: 10 | L14: 11 | M14: 12 | N14: 13 | O14: 14 | P14: 15 | Q14: 16 | R14: 17 | S14: 18 | T14: 19 | U14: 20 | V14: 21 | W14: 22 | X14: 23 | Y14: 24 | Z14: 25 | AA14: 26 | AB14: 27 | AC14: 28 | AD14: 29 | AE14: 30 | AF14: 31
A15: CA REALISE (CLIENT CESSION GARANTIE) | C15: 0 | D15: 95 | E15: 353 | F15: 927 | I15: 927 | J15: 927 | K15: 945 | L15: 945 | M15: 1003.61 | P15: 1108 | Q15: 1110 | R15: 3757 | S15: 4580 | T15: 4814 | W15: 4974 | X15: 5504 | Y15: 6388 | Z15: 6565 | AA15: 7493 | AD15: 7856 | AE15: 8049 | AF15: 8434
A16: OBJECTIF | C16: 792 | D16: =C16+792 -> 1584 | E16: =D16+792 -> 2376 | F16: =E16+792 -> 3168 | I16: =F16+792 -> 3960 | J16: =I16+792 -> 4752 | K16: =J16+792 -> 5544 | L16: =K16+792 -> 6336 | M16: =L16+792 -> 7128 | P16: =M16+792 -> 7920 | Q16: =P16+792 -> 8712 | R16: =Q16+792 -> 9504 | S16: =R16+792 -> 10296 | T16: =S16+792 -> 11088 | W16: =T16+792 -> 11880 | X16: =W16+792 -> 12672 | Y16: =X16+792 -> 13464 | Z16: =Y16+792 -> 14256 | AA16: =Z16+792 -> 15048 | AD16: =AA16+792 -> 15840 | AE16: =AD16+792 -> 16632 | AF16: =AE16+792 -> 17424
A17: % DE REALISATION | C17: =C15/C16 -> 0 | D17: =D15/D16 -> 0.059974747 | E17: =E15/E16 -> 0.14856902 | F17: =F15/F16 -> 0.29261364 | I17: =I15/I16 -> 0.23409091 | J17: =J15/J16 -> 0.19507576 | K17: =K15/K16 -> 0.17045455 | L17: =L15/L16 -> 0.14914773 | M17: =M15/M16 -> 0.14079826 | P17: =P15/P16 -> 0.13989899 | Q17: =Q15/Q16 -> 0.12741047 | R17: =R15/R16 -> 0.39530724 | S17: =S15/S16 -> 0.44483294 | T17: =T15/T16 -> 0.43416306 | W17: =W15/W16 -> 0.41868687 | X17: =X15/X16 -> 0.43434343 | Y17: =Y15/Y16 -> 0.47445039 | Z17: =Z15/Z16 -> 0.46050786 | AA17: =AA15/AA16 -> 0.49793993 | AD17: =AD15/AD16 -> 0.4959596 | AE17: =AE15/AE16 -> 0.48394661 | AF17: =AF15/AF16 -> 0.484045
A21: PRESTIGE AUTO MONTPELLIER | B21: 1 | C21: 2 | D21: 3 | E21: 4 | F21: 5 | G21: 6 | H21: 7 | I21: 8 | J21: 9 | K21: 10 | L21: 11 | M21: 12 | N21: 13 | O21: 14 | P21: 15 | Q21: 16 | R21: 17 | S21: 18 | T21: 19 | U21: 20 | V21: 21 | W21: 22 | X21: 23 | Y21: 24 | Z21: 25 | AA21: 26 | AB21: 27 | AC21: 28 | AD21: 29 | AE21: 30 | AF21: 31
A22: CA REALISE (CLIENT CESSION GARANTIE) | C22: 925 | D22: 1857 | E22: 3542 | F22: 7304 | I22: 9380 | J22: 10581 | K22: 13032 | L22: 16192 | M22: 20376 | P22: 20693 | Q22: 22764 | R22: 23920 | S22: 26455 | T22: 29232 | W22: 33487 | X22: 35183 | Y22: 37728 | Z22: 39945 | AA22: 42678 | AD22: 45952 | AE22: 51332 | AF22: 56371
A23: OBJECTIF | C23: 2877 | D23: =C23+2877 -> 5754 | E23: =D23+2877 -> 8631 | F23: =E23+287 -> 8918 | I23: =F23+2877 -> 11795 | J23: =I23+2877 -> 14672 | K23: =J23+2877 -> 17549 | L23: =K23+2877 -> 20426 | M23: =L23+2877 -> 23303 | P23: =M23+2877 -> 26180 | Q23: =P23+2877 -> 29057 | R23: =Q23+2877 -> 31934 | S23: =R23+2877 -> 34811 | T23: =S23+2877 -> 37688 | W23: =T23+2877 -> 40565 | X23: =W23+2877 -> 43442 | Y23: =X23+2877 -> 46319 | Z23: =Y23+2877 -> 49196 | AA23: =Z23+2877 -> 52073 | AD23: =AA23+2877 -> 54950 | AE23: =AD23+2877 -> 57827 | AF23: =AE23+2877 -> 60704
A24: % DE REALISATION | C24: =C22/C23 -> 0.32151547 | D24: =D22/D23 -> 0.32273201 | E24: =E22/E23 -> 0.41038118 | F24: =F22/F23 -> 0.81901772 | I24: =I22/I23 -> 0.79525223 | J24: =J22/J23 -> 0.72116957 | K24: =K22/K23 -> 0.74260642 | L24: =L22/L23 -> 0.79271517 | M24: =M22/M23 -> 0.87439385 | P24: =P22/P23 -> 0.79041253 | Q24: =Q22/Q23 -> 0.78342568 | R24: =R22/R23 -> 0.74904491 | S24: =S22/S23 -> 0.75996093 | T24: =T22/T23 -> 0.7756315 | W24: =W22/W23 -> 0.82551461 | X24: =X22/X23 -> 0.80988444 | Y24: =Y22/Y23 -> 0.81452536 | Z24: =Z22/Z23 -> 0.81195626 | AA24: =AA22/AA23 -> 0.8195802 | AD24: =AD22/AD23 -> 0.83625114 | AE24: =AE22/AE23 -> 0.88768222 | AF24: =AF22/AF23 -> 0.92862085
A28: PRESTIGE AUTO NIMES | B28: 1 | C28: 2 | D28: 3 | E28: 4 | F28: 5 | G28: 6 | H28: 7 | I28: 8 | J28: 9 | K28: 10 | L28: 11 | M28: 12 | N28: 13 | O28: 14 | P28: 15 | Q28: 16 | R28: 17 | S28: 18 | T28: 19 | U28: 20 | V28: 21 | W28: 22 | X28: 23 | Y28: 24 | Z28: 25 | AA28: 26 | AB28: 27 | AC28: 28 | AD28: 29 | AE28: 30 | AF28: 31
A29: CA REALISE (CLIENT CESSION GARANTIE) | C29: 848 | D29: 1545 | E29: 1545 | F29: 1999 | I29: 3441 | J29: 3622 | K29: 3642 | L29: 5790 | M29: 6659 | P29: 7401 | Q29: 8607 | R29: 11246 | S29: 12002 | T29: 12901 | W29: 14001 | X29: 15273 | Y29: 17557 | Z29: 18239 | AA29: 19240 | AD29: 19676 | AE29: 19917 | AF29: 23002
A30: OBJECTIF | C30: 1770 | D30: =C30+1770 -> 3540 | E30: =D30+1770 -> 5310 | F30: =E30+1770 -> 7080 | I30: =F30+1770 -> 8850 | J30: =I30+1770 -> 10620 | K30: =J30+1770 -> 12390 | L30: =K30+1770 -> 14160 | M30: =L30+1770 -> 15930 | P30: =M30+1770 -> 17700 | Q30: =P30+1770 -> 19470 | R30: =Q30+1770 -> 21240 | S30: =R30+1770 -> 23010 | T30: =S30+1770 -> 24780 | W30: =T30+1770 -> 26550 | X30: =W30+1770 -> 28320 | Y30: =X30+1770 -> 30090 | Z30: =Y30+1770 -> 31860 | AA30: =Z30+1770 -> 33630 | AD30: =AA30+1770 -> 35400 | AE30: =AD30+1770 -> 37170 | AF30: =AE30+1770 -> 38940
A31: % DE REALISATION | C31: =C29/C30 -> 0.47909605 | D31: =D29/D30 -> 0.43644068 | E31: =E29/E30 -> 0.29096045 | F31: =F29/F30 -> 0.28234463 | I31: =I29/I30 -> 0.38881356 | J31: =J29/J30 -> 0.34105461 | K31: =K29/K30 -> 0.29394673 | L31: =L29/L30 -> 0.40889831 | M31: =M29/M30 -> 0.41801632 | P31: =P29/P30 -> 0.41813559 | Q31: =Q29/Q30 -> 0.44206471 | R31: =R29/R30 -> 0.52947269 | S31: =S29/S30 -> 0.5215993 | T31: =T29/T30 -> 0.52062147 | W31: =W29/W30 -> 0.52734463 | X31: =X29/X30 -> 0.53930085 | Y31: =Y29/Y30 -> 0.58348288 | Z31: =Z29/Z30 -> 0.57247332 | AA31: =AA29/AA30 -> 0.57210824 | AD31: =AD29/AD30 -> 0.55581921 | AE31: =AE29/AE30 -> 0.53583535 | AF31: =AF29/AF30 -> 0.59070365
A35: FORD LATTES | B35: 1 | C35: 2 | D35: 3 | E35: 4 | F35: 5 | G35: 6 | H35: 7 | I35: 8 | J35: 9 | K35: 10 | L35: 11 | M35: 12 | N35: 13 | O35: 14 | P35: 15 | Q35: 16 | R35: 17 | S35: 18 | T35: 19 | U35: 20 | V35: 21 | W35: 22 | X35: 23 | Y35: 24 | Z35: 25 | AA35: 26 | AB35: 27 | AC35: 28 | AD35: 29 | AE35: 30 | AF35: 31
A36: CA REALISE (CLIENT CESSION GARANTIE) | C36: 935 | D36: 3468 | E36: 4980 | F36: 7146 | I36: 8519 | J36: 10062 | K36: 12675 | L36: 14852 | M36: 16621 | P36: 22812 | Q36: 24766 | R36: 28022 | S36: 29962 | T36: 32080 | W36: 36020 | X36: 39332 | Y36: 43313 | Z36: 46763 | AA36: 49230 | AD36: 50176 | AE36: 56565 | AF36: 60653
A37: OBJECTIF | C37: 3262 | D37: =C37+3262 -> 6524 | E37: =D37+3262 -> 9786 | F37: =E37+3262 -> 13048 | I37: =F37+3262 -> 16310 | J37: =I37+3262 -> 19572 | K37: =J37+3262 -> 22834 | L37: =K37+3262 -> 26096 | M37: =L37+3262 -> 29358 | P37: =M37+3262 -> 32620 | Q37: =P37+3262 -> 35882 | R37: =Q37+3262 -> 39144 | S37: =R37+3262 -> 42406 | T37: =S37+3262 -> 45668 | W37: =T37+3262 -> 48930 | X37: =W37+3262 -> 52192 | Y37: =X37+3262 -> 55454 | Z37: =Y37+3262 -> 58716 | AA37: =Z37+3262 -> 61978 | AD37: =AA37+3262 -> 65240 | AE37: =AD37+3262 -> 68502 | AF37: =AE37+3262 -> 71764
A38: % DE REALISATION | C38: =C36/C37 -> 0.28663397 | D38: =D36/D37 -> 0.53157572 | E38: =E36/E37 -> 0.50889025 | F38: =F36/F37 -> 0.54767014 | I38: =I36/I37 -> 0.5223176 | J38: =J36/J37 -> 0.51410178 | K38: =K36/K37 -> 0.55509328 | L38: =L36/L37 -> 0.56912937 | M38: =M36/M37 -> 0.56614892 | P38: =P36/P37 -> 0.69932557 | Q38: =Q36/Q37 -> 0.69020679 | R38: =R36/R37 -> 0.71586961 | S38: =S36/S37 -> 0.70655096 | T38: =T36/T37 -> 0.70246124 | W38: =W36/W37 -> 0.73615369 | X38: =X36/X37 -> 0.75360208 | Y38: =Y36/Y37 -> 0.78106178 | Z38: =Z36/Z37 -> 0.79642687 | AA38: =AA36/AA37 -> 0.79431411 | AD38: =AD36/AD37 -> 0.76909871 | AE38: =AE36/AE37 -> 0.82574231 | AF38: =AF36/AF37 -> 0.84517307
A42: FORD PEROLS | B42: 1 | C42: 2 | D42: 3 | E42: 4 | F42: 5 | G42: 6 | H42: 7 | I42: 8 | J42: 9 | K42: 10 | L42: 11 | M42: 12 | N42: 13 | O42: 14 | P42: 15 | Q42: 16 | R42: 17 | S42: 18 | T42: 19 | U42: 20 | V42: 21 | W42: 22 | X42: 23 | Y42: 24 | Z42: 25 | AA42: 26 | AB42: 27 | AC42: 28 | AD42: 29 | AE42: 30 | AF42: 31
A43: CA REALISE (CLIENT CESSION GARANTIE) | C43: 19 | D43: 211 | E43: 300 | F43: 348 | I43: 763 | J43: 895 | K43: 1001 | L43: 1814 | M43: 2455 | P43: 2865 | Q43: 3279 | R43: 4752 | S43: 5348 | T43: 6143 | W43: 7537 | X43: 8012 | Y43: 8689 | Z43: 10185 | AA43: 10992 | AD43: 11980 | AE43: 13204 | AF43: 13444
A44: OBJECTIF | C44: 731 | D44: =C44+731 -> 1462 | E44: =D44+731 -> 2193 | F44: =E44+731 -> 2924 | I44: =F44+731 -> 3655 | J44: =I44+731 -> 4386 | K44: =J44+731 -> 5117 | L44: =K44+731 -> 5848 | M44: =L44+731 -> 6579 | P44: =M44+731 -> 7310 | Q44: =P44+731 -> 8041 | R44: =Q44+731 -> 8772 | S44: =R44+731 -> 9503 | T44: =S44+731 -> 10234 | W44: =T44+731 -> 10965 | X44: =W44+731 -> 11696 | Y44: =X44+731 -> 12427 | Z44: =Y44+731 -> 13158 | AA44: =Z44+731 -> 13889 | AD44: =AA44+731 -> 14620 | AE44: =AD44+731 -> 15351 | AF44: =AE44+731 -> 16082
A45: % DE REALISATION | C45: =C43/C44 -> 0.025991792 | D45: =D43/D44 -> 0.14432285 | E45: =E43/E44 -> 0.13679891 | F45: =F43/F44 -> 0.11901505 | I45: =I43/I44 -> 0.20875513 | J45: =J43/J44 -> 0.20405837 | K45: =K43/K44 -> 0.19562244 | L45: =L43/L44 -> 0.31019152 | M45: =M43/M44 -> 0.37315701 | P45: =P43/P44 -> 0.39192886 | Q45: =Q43/Q44 -> 0.4077851 | R45: =R43/R44 -> 0.54172367 | S45: =S43/S44 -> 0.56276965 | T45: =T43/T44 -> 0.60025406 | W45: =W43/W44 -> 0.6873689 | X45: =X43/X44 -> 0.68502052 | Y45: =Y43/Y44 -> 0.69920335 | Z45: =Z43/Z44 -> 0.77405381 | AA45: =AA43/AA44 -> 0.79141767 | AD45: =AD43/AD44 -> 0.81942544 | AE45: =AE43/AE44 -> 0.8601394 | AF45: =AF43/AF44 -> 0.83596568
A48: SETE | B48: 1 | C48: 2 | D48: 3 | E48: 4 | F48: 5 | G48: 6 | H48: 7 | I48: 8 | J48: 9 | K48: 10 | L48: 11 | M48: 12 | N48: 13 | O48: 14 | P48: 15 | Q48: 16 | R48: 17 | S48: 18 | T48: 19 | U48: 20 | V48: 21 | W48: 22 | X48: 23 | Y48: 24 | Z48: 25 | AA48: 26 | AB48: 27 | AC48: 28 | AD48: 29 | AE48: 30 | AF48: 31
A49: CA REALISE (CLIENT CESSION GARANTIE) | C49: 174 | D49: 586 | E49: 747 | F49: 1347 | I49: 1443 | J49: 2281 | K49: 2705 | L49: 3218 | M49: 3320 | P49: 3625 | Q49: 4019 | R49: 4691 | S49: 5067 | T49: 5213 | W49: 5756 | X49: 6066 | Y49: 6652 | Z49: 6882 | AA49: 7114 | AD49: 8975 | AE49: 10003 | AF49: 12649
A50: OBJECTIF | C50: 515 | D50: =C50+515 -> 1030 | E50: =D50+515 -> 1545 | F50: =E50+515 -> 2060 | I50: =F50+515 -> 2575 | J50: =I50+515 -> 3090 | K50: =J50+515 -> 3605 | L50: =K50+515 -> 4120 | M50: =L50+515 -> 4635 | P50: =M50+515 -> 5150 | Q50: =P50+515 -> 5665 | R50: =Q50+515 -> 6180 | S50: =R50+515 -> 6695 | T50: =S50+515 -> 7210 | W50: =T50+515 -> 7725 | X50: =W50+515 -> 8240 | Y50: =X50+515 -> 8755 | Z50: =Y50+515 -> 9270 | AA50: =Z50+515 -> 9785 | AD50: =AA50+515 -> 10300 | AE50: =AD50+515 -> 10815 | AF50: =AE50+515 -> 11330
A51: % DE REALISATION | C51: =C49/C50 -> 0.33786408 | D51: =D49/D50 -> 0.56893204 | E51: =E49/E50 -> 0.48349515 | F51: =F49/F50 -> 0.6538835 | I51: =I49/I50 -> 0.56038835 | J51: =J49/J50 -> 0.7381877 | K51: =K49/K50 -> 0.75034674 | L51: =L49/L50 -> 0.78106796 | M51: =M49/M50 -> 0.7162891 | P51: =P49/P50 -> 0.7038835 | Q51: =Q49/Q50 -> 0.70944395 | R51: =R49/R50 -> 0.75906149 | S51: =S49/S50 -> 0.75683346 | T51: =T49/T50 -> 0.72302358 | W51: =W49/W50 -> 0.74511327 | X51: =X49/X50 -> 0.73616505 | Y51: =Y49/Y50 -> 0.7597944 | Z51: =Z49/Z50 -> 0.74239482 | AA51: =AA49/AA50 -> 0.72703117 | AD51: =AD49/AD50 -> 0.87135922 | AE51: =AE49/AE50 -> 0.92491909 | AF51: =AF49/AF50 -> 1.1164166
A55: CARROSSERIE ST JEAN DE VEDAS | B55: 1 | C55: 2 | D55: 3 | E55: 4 | F55: 5 | G55: 6 | H55: 7 | I55: 8 | J55: 9 | K55: 10 | L55: 11 | M55: 12 | N55: 13 | O55: 14 | P55: 15 | Q55: 16 | R55: 17 | S55: 18 | T55: 19 | U55: 20 | V55: 21 | W55: 22 | X55: 23 | Y55: 24 | Z55: 25 | AA55: 26 | AB55: 27 | AC55: 28 | AD55: 29 | AE55: 30 | AF55: 31
A56: CA REALISE (CLIENT CESSION GARANTIE) | C56: 1032 | D56: 2323 | E56: 3263 | F56: 5957 | I56: 5957 | J56: 9513 | K56: 12243 | L56: 12762 | M56: 18327 | P56: 18655 | Q56: 20989 | R56: 23347 | S56: 29905 | T56: 31598 | W56: 32263 | X56: 33212 | Y56: 34517 | Z56: 38075 | AA56: 39633 | AD56: 41392 | AE56: 43013 | AF56: 44676
A57: OBJECTIF | C57: 2004 | D57: =C57+2004 -> 4008 | E57: =D57+2004 -> 6012 | F57: =E57+2004 -> 8016 | I57: =F57+2004 -> 10020 | J57: =I57+2004 -> 12024 | K57: =J57+2004 -> 14028 | L57: =K57+2004 -> 16032 | M57: =L57+2004 -> 18036 | P57: =M57+2004 -> 20040 | Q57: =P57+2004 -> 22044 | R57: =Q57+2004 -> 24048 | S57: =R57+2004 -> 26052 | T57: =S57+2004 -> 28056 | W57: =T57+2004 -> 30060 | X57: =W57+2004 -> 32064 | Y57: =X57+2004 -> 34068 | Z57: =Y57+2004 -> 36072 | AA57: =Z57+2004 -> 38076 | AD57: =AA57+2004 -> 40080 | AE57: =AD57+2004 -> 42084 | AF57: =AE57+2004 -> 44088
A58: % DE REALISATION | C58: =C56/C57 -> 0.51497006 | D58: =D56/D57 -> 0.57959082 | E58: =E56/E57 -> 0.54274784 | F58: =F56/F57 -> 0.74313872 | I58: =I56/I57 -> 0.59451098 | J58: =J56/J57 -> 0.79116766 | K58: =K56/K57 -> 0.87275449 | L58: =L56/L57 -> 0.79603293 | M58: =M56/M57 -> 1.0161344 | P58: =P56/P57 -> 0.93088822 | Q58: =Q56/Q57 -> 0.95214117 | R58: =R56/R57 -> 0.97084997 | S58: =S56/S57 -> 1.1478965 | T58: =T56/T57 -> 1.1262475 | W58: =W56/W57 -> 1.0732868 | X58: =X56/X57 -> 1.0358034 | Y58: =Y56/Y57 -> 1.0131795 | Z58: =Z56/Z57 -> 1.0555278 | AA58: =AA56/AA57 -> 1.0408919 | AD58: =AD56/AD57 -> 1.0327345 | AE58: =AE56/AE57 -> 1.0220749 | AF58: =AF56/AF57 -> 1.013337
A62: FORD RODEZ | B62: 1 | C62: 2 | D62: 3 | E62: 4 | F62: 5 | G62: 6 | H62: 7 | I62: 8 | J62: 9 | K62: 10 | L62: 11 | M62: 12 | N62: 13 | O62: 14 | P62: 15 | Q62: 16 | R62: 17 | S62: 18 | T62: 19 | U62: 20 | V62: 21 | W62: 22 | X62: 23 | Y62: 24 | Z62: 25 | AA62: 26 | AB62: 27 | AC62: 28 | AD62: 29 | AE62: 30 | AF62: 31
A63: CA REALISE (CLIENT CESSION GARANTIE) | C63: 255 | D63: 514 | E63: 1595 | F63: 2166 | I63: 2428 | J63: 3346 | K63: 3987 | L63: 4669 | M63: 5283 | P63: 5806 | Q63: 6452 | R63: 7265 | S63: 7995 | T63: 9257 | W63: 10335 | X63: 11167 | Y63: 11968 | Z63: 12325 | AA63: 12811 | AD63: 13315 | AE63: 13737 | AF63: 14565
A64: OBJECTIF | C64: 913 | D64: =C64+913 -> 1826 | E64: =D64+913 -> 2739 | F64: =E64+913 -> 3652 | I64: =F64+913 -> 4565 | J64: =I64+913 -> 5478 | K64: =J64+913 -> 6391 | L64: =K64+913 -> 7304 | M64: =L64+913 -> 8217 | P64: =M64+913 -> 9130 | Q64: =P64+913 -> 10043 | R64: =Q64+913 -> 10956 | S64: =R64+913 -> 11869 | T64: =S64+913 -> 12782 | W64: =T64+913 -> 13695 | X64: =W64+913 -> 14608 | Y64: =X64+913 -> 15521 | Z64: =Y64+913 -> 16434 | AA64: =Z64+913 -> 17347 | AD64: =AA64+91 -> 17438 | AE64: =AD64+913 -> 18351 | AF64: =AE64+913 -> 19264
A65: % DE REALISATION | C65: =C63/C64 -> 0.27929901 | D65: =D63/D64 -> 0.28148959 | E65: =E63/E64 -> 0.58232932 | F65: =F63/F64 -> 0.59309967 | I65: =I63/I64 -> 0.53187295 | J65: =J63/J64 -> 0.61080686 | K65: =K63/K64 -> 0.62384603 | L65: =L63/L64 -> 0.63923877 | M65: =M63/M64 -> 0.64293538 | P65: =P63/P64 -> 0.63592552 | Q65: =Q63/Q64 -> 0.64243752 | R65: =R63/R64 -> 0.66310697 | S65: =S63/S64 -> 0.6736035 | T65: =T63/T64 -> 0.72422156 | W65: =W63/W64 -> 0.75465498 | X65: =X63/X64 -> 0.76444414 | Y65: =Y63/Y64 -> 0.77108434 | Z65: =Z63/Z64 -> 0.74996958 | AA65: =AA63/AA64 -> 0.73851386 | AD65: =AD63/AD64 -> 0.76356234 | AE65: =AE63/AE64 -> 0.74856956 | AF65: =AF63/AF64 -> 0.7560735
A69: LAND ROVER RODEZ | B69: 1 | C69: 2 | D69: 3 | E69: 4 | F69: 5 | G69: 6 | H69: 7 | I69: 8 | J69: 9 | K69: 10 | L69: 11 | M69: 12 | N69: 13 | O69: 14 | P69: 15 | Q69: 16 | R69: 17 | S69: 18 | T69: 19 | U69: 20 | V69: 21 | W69: 22 | X69: 23 | Y69: 24 | Z69: 25 | AA69: 26 | AB69: 27 | AC69: 28 | AD69: 29 | AE69: 30 | AF69: 31
...

Sheet Février 2018
C1: Suivi objectif réalisation CA par atelier
AE4: =20 -> 20
S5: 5188
A7: GRIM PASSION LATTES | B7: 1 | C7: 2 | D7: 3 | E7: 4 | F7: 5 | G7: 6 | H7: 7 | I7: 8 | J7: 9 | K7: 10 | L7: 11 | M7: 12 | N7: 13 | O7: 14 | P7: 15 | Q7: 16 | R7: 17 | S7: 18 | T7: 19 | U7: 20 | V7: 21 | W7: 22 | X7: 23 | Y7: 24 | Z7: 25 | AA7: 26 | AB7: 27 | AC7: 28
A8: CA REALISE (CLIENT CESSION GARANTIE) | B8: 5140 | C8: 9377 | F8: 13103 | G8: 19795 | H8: 24383 | I8: 31035 | J8: 39045 | M8: 44206 | N8: 50393 | O8: 53762 | P8: 57311 | Q8: 66565 | T8: 68749 | U8: 74818 | V8: 81201 | W8: 88607 | X8: 94536 | AA8: 97967 | AB8: 102938 | AC8: 106079
A9: OBJECTIF | B9: 5856 | C9: =B9+5856 -> 11712 | F9: =C9+5856 -> 17568 | G9: =F9+5856 -> 23424 | H9: =G9+5856 -> 29280 | I9: =H9+5856 -> 35136 | J9: =I9+5856 -> 40992 | M9: =J9+5856 -> 46848 | N9: =M9+5856 -> 52704 | O9: =N9+5856 -> 58560 | P9: =O9+5856 -> 64416 | Q9: =P9+5856 -> 70272 | T9: =Q9+5856 -> 76128 | U9: =T9+5856 -> 81984 | V9: =U9+5856 -> 87840 | W9: =V9+5856 -> 93696 | X9: =W9+5856 -> 99552 | AA9: =X9+5856 -> 105408 | AB9: =AA9+5856 -> 111264 | AC9: =AB9+5856 -> 117120
A10: % DE REALISATION | B10: =B8/B9 -> 0.87773224 | C10: =C8/C9 -> 0.80063183 | F10: =F8/F9 -> 0.74584472 | G10: =G8/G9 -> 0.84507343 | H10: =H8/H9 -> 0.83275273 | I10: =I8/I9 -> 0.8832821 | J10: =J8/J9 -> 0.95250293 | M10: =M8/M9 -> 0.94360485 | N10: =N8/N9 -> 0.95615134 | O10: =O8/O9 -> 0.91806694 | P10: =P8/P9 -> 0.88970132 | Q10: =Q8/Q9 -> 0.94724784 | T10: =T8/T9 -> 0.90307114 | U10: =U8/U9 -> 0.9125927 | V10: =V8/V9 -> 0.9244194 | W10: =W8/W9 -> 0.94568605 | X10: =X8/X9 -> 0.94961427 | AA10: =AA8/AA9 -> 0.92940764 | AB10: =AB8/AB9 -> 0.92516897 | AC10: =AC8/AC9 -> 0.90572917
A14: GRIM PASSION PEROLS | B14: 1 | C14: 2 | D14: 3 | E14: 4 | F14: 5 | G14: 6 | H14: 7 | I14: 8 | J14: 9 | K14: 10 | L14: 11 | M14: 12 | N14: 13 | O14: 14 | P14: 15 | Q14: 16 | R14: 17 | S14: 18 | T14: 19 | U14: 20 | V14: 21 | W14: 22 | X14: 23 | Y14: 24 | Z14: 25 | AA14: 26 | AB14: 27 | AC14: 28
A15: CA REALISE (CLIENT CESSION GARANTIE) | B15: 2168 | C15: 2900 | F15: 3488 | G15: 3514 | H15: 3514 | I15: 4292 | J15: 4638 | M15: 5854 | N15: 6407 | O15: 7231 | P15: 8136 | Q15: 9332 | T15: 9942 | U15: 10258 | V15: 11644 | W15: 11644 | X15: 11933 | AA15: 12021 | AB15: 12409 | AC15: 12409
A16: OBJECTIF | B16: 792 | C16: =B16+792 -> 1584 | F16: =C16+792 -> 2376 | G16: =F16+792 -> 3168 | H16: =G16+792 -> 3960 | I16: =H16+792 -> 4752 | J16: =I16+792 -> 5544 | M16: =J16+792 -> 6336 | N16: =M16+792 -> 7128 | O16: =N16+792 -> 7920 | P16: =O16+792 -> 8712 | Q16: =P16+792 -> 9504 | T16: =Q16+792 -> 10296 | U16: =T16+792 -> 11088 | V16: =U16+792 -> 11880 | W16: =V16+792 -> 12672 | X16: =W16+792 -> 13464 | AA16: =X16+792 -> 14256 | AB16: =AA16+792 -> 15048 | AC16: =AB16+792 -> 15840
A17: % DE REALISATION | B17: =B15/B16 -> 2.7373737 | C17: =C15/C16 -> 1.8308081 | F17: =F15/F16 -> 1.4680135 | G17: =G15/G16 -> 1.1092172 | H17: =H15/H16 -> 0.88737374 | I17: =I15/I16 -> 0.90319865 | J17: =J15/J16 -> 0.83658009 | M17: =M15/M16 -> 0.92392677 | N17: =N15/N16 -> 0.89884961 | O17: =O15/O16 -> 0.91300505 | P17: =P15/P16 -> 0.9338843 | Q17: =Q15/Q16 -> 0.98190236 | T17: =T15/T16 -> 0.96561772 | U17: =U15/U16 -> 0.9251443 | V17: =V15/V16 -> 0.98013468 | W17: =W15/W16 -> 0.91887626 | X17: =X15/X16 -> 0.88628936 | AA17: =AA15/AA16 -> 0.84322391 | AB17: =AB15/AB16 -> 0.82462786 | AC17: =AC15/AC16 -> 0.78339646
A21: PRESTIGE AUTO MONTPELLIER | B21: 1 | C21: 2 | D21: 3 | E21: 4 | F21: 5 | G21: 6 | H21: 7 | I21: 8 | J21: 9 | K21: 10 | L21: 11 | M21: 12 | N21: 13 | O21: 14 | P21: 15 | Q21: 16 | R21: 17 | S21: 18 | T21: 19 | U21: 20 | V21: 21 | W21: 22 | X21: 23 | Y21: 24 | Z21: 25 | AA21: 26 | AB21: 27 | AC21: 28
A22: CA REALISE (CLIENT CESSION GARANTIE) | B22: 1595 | C22: 4356 | F22: 4623 | G22: 5927 | H22: 7383 | I22: 11742 | J22: 14708 | M22: 17106 | N22: 17975 | O22: 18413 | P22: 20860 | Q22: 23542 | T22: 26352 | U22: 27215 | V22: 29700 | W22: 32184 | X22: 34083 | AA22: 37374 | AB22: 38696 | AC22: 39426
A23: OBJECTIF | B23: 2877 | C23: =B23+2877 -> 5754 | F23: =C23+2877 -> 8631 | G23: =F23+2877 -> 11508 | H23: =G23+2877 -> 14385 | I23: =H23+2877 -> 17262 | J23: =I23+2877 -> 20139 | M23: =J23+2877 -> 23016 | N23: =M23+2877 -> 25893 | O23: =N23+2877 -> 28770 | P23: =O23+2877 -> 31647 | Q23: =P23+2877 -> 34524 | T23: =Q23+2877 -> 37401 | U23: =T23+2877 -> 40278 | V23: =U23+2877 -> 43155 | W23: =V23+2877 -> 46032 | X23: =W23+2877 -> 48909 | AA23: =X23+2877 -> 51786 | AB23: =AA23+2877 -> 54663 | AC23: =AB23+3266 -> 57929
A24: % DE REALISATION | B24: =B22/B23 -> 0.55439694 | C24: =C22/C23 -> 0.75703858 | F24: =F22/F23 -> 0.53562739 | G24: =G22/G23 -> 0.51503302 | H24: =H22/H23 -> 0.51324296 | I24: =I22/I23 -> 0.68022245 | J24: =J22/J23 -> 0.73032425 | M24: =M22/M23 -> 0.74322211 | N24: =N22/N23 -> 0.69420307 | O24: =O22/O23 -> 0.64000695 | P24: =P22/P23 -> 0.65914621 | Q24: =Q22/Q23 -> 0.68190244 | T24: =T22/T23 -> 0.70458009 | U24: =U22/U23 -> 0.67567903 | V24: =V22/V23 -> 0.68821689 | W24: =W22/W23 -> 0.6991658 | X24: =X22/X23 -> 0.69686561 | AA24: =AA22/AA23 -> 0.72170085 | AB24: =AB22/AB23 -> 0.70790114 | AC24: =AC22/AC23 -> 0.68059176
A28: PRESTIGE AUTO NIMES | B28: 1 | C28: 2 | D28: 3 | E28: 4 | F28: 5 | G28: 6 | H28: 7 | I28: 8 | J28: 9 | K28: 10 | L28: 11 | M28: 12 | N28: 13 | O28: 14 | P28: 15 | Q28: 16 | R28: 17 | S28: 18 | T28: 19 | U28: 20 | V28: 21 | W28: 22 | X28: 23 | Y28: 24 | Z28: 25 | AA28: 26 | AB28: 27 | AC28: 28
A29: CA REALISE (CLIENT CESSION GARANTIE) | B29: 358 | C29: 3046 | F29: 3652 | G29: 4934 | H29: 5819 | I29: 9353 | J29: 11600 | M29: 12045 | N29: 13706 | O29: 15316 | P29: 16498 | Q29: 16548 | T29: 16548 | U29: 17417 | V29: 18073 | W29: 18992 | X29: 20109 | AA29: 20557 | AB29: 25181 | AC29: 27940
A30: OBJECTIF | B30: 1770 | C30: =B30+1770 -> 3540 | F30: =C30+1770 -> 5310 | G30: =F30+1770 -> 7080 | H30: =G30+1770 -> 8850 | I30: =H30+1770 -> 10620 | J30: =I30+1770 -> 12390 | M30: =J30+1770 -> 14160 | N30: =M30+1770 -> 15930 | O30: =N30+1770 -> 17700 | P30: =O30+1770 -> 19470 | Q30: =P30+1770 -> 21240 | T30: =Q30+1770 -> 23010 | U30: =T30+1770 -> 24780 | V30: =U30+1770 -> 26550 | W30: =V30+1770 -> 28320 | X30: =W30+1770 -> 30090 | AA30: =X30+1770 -> 31860 | AB30: =AA30+1770 -> 33630 | AC30: =AB30+1770 -> 35400
A31: % DE REALISATION | B31: =B29/B30 -> 0.20225989 | C31: =C29/C30 -> 0.86045198 | F31: =F29/F30 -> 0.68775895 | G31: =G29/G30 -> 0.69689266 | H31: =H29/H30 -> 0.65751412 | I31: =I29/I30 -> 0.8806968 | J31: =J29/J30 -> 0.9362389 | M31: =M29/M30 -> 0.85063559 | N31: =N29/N30 -> 0.8603892 | O31: =O29/O30 -> 0.86531073 | P31: =P29/P30 -> 0.8473549 | Q31: =Q29/Q30 -> 0.77909605 | T31: =T29/T30 -> 0.71916558 | U31: =U29/U30 -> 0.70286521 | V31: =V29/V30 -> 0.68071563 | W31: =W29/W30 -> 0.67062147 | X31: =X29/X30 -> 0.66829511 | AA31: =AA29/AA30 -> 0.64522913 | AB31: =AB29/AB30 -> 0.74876598 | AC31: =AC29/AC30 -> 0.78926554
A35: FORD LATTES | B35: 1 | C35: 2 | D35: 3 | E35: 4 | F35: 5 | G35: 6 | H35: 7 | I35: 8 | J35: 9 | K35: 10 | L35: 11 | M35: 12 | N35: 13 | O35: 14 | P35: 15 | Q35: 16 | R35: 17 | S35: 18 | T35: 19 | U35: 20 | V35: 21 | W35: 22 | X35: 23 | Y35: 24 | Z35: 25 | AA35: 26 | AB35: 27 | AC35: 28
A36: CA REALISE (CLIENT CESSION GARANTIE) | B36: 2240 | C36: 5507 | F36: 8033 | G36: 10294 | H36: 12296 | I36: 15184 | J36: 19525 | M36: 22821 | N36: 26029 | O36: 28937 | P36: 33730 | Q36: 36899 | T36: 38855 | U36: 41006 | V36: 43322 | W36: 45188 | X36: 48412 | AA36: 50572 | AB36: 53887 | AC36: 58609
A37: OBJECTIF | B37: 3262 | C37: =B37+3262 -> 6524 | F37: =C37+3262 -> 9786 | G37: =F37+3262 -> 13048 | H37: =G37+3262 -> 16310 | I37: =H37+3262 -> 19572 | J37: =I37+3262 -> 22834 | M37: =J37+3262 -> 26096 | N37: =M37+3262 -> 29358 | O37: =N37+3262 -> 32620 | P37: =O37+3262 -> 35882 | Q37: =P37+3262 -> 39144 | T37: =Q37+3262 -> 42406 | U37: =T37+3262 -> 45668 | V37: =U37+3262 -> 48930 | W37: =V37+3262 -> 52192 | X37: =W37+3262 -> 55454 | AA37: =X37+3262 -> 58716 | AB37: =AA37+3262 -> 61978 | AC37: =AB37+3262 -> 65240
A38: % DE REALISATION | B38: =B36/B37 -> 0.68669528 | C38: =C36/C37 -> 0.84411404 | F38: =F36/F37 -> 0.82086654 | G38: =G36/G37 -> 0.78893317 | H38: =H36/H37 -> 0.75389332 | I38: =I36/I37 -> 0.77580217 | J38: =J36/J37 -> 0.85508452 | M38: =M36/M37 -> 0.87450184 | N38: =N36/N37 -> 0.88660672 | O38: =O36/O37 -> 0.88709381 | P38: =P36/P37 -> 0.94002564 | Q38: =Q36/Q37 -> 0.94264766 | T38: =T36/T37 -> 0.91626185 | U38: =U36/U37 -> 0.89791539 | V38: =V36/V37 -> 0.88538729 | W38: =W36/W37 -> 0.86580319 | X38: =X36/X37 -> 0.87301187 | AA38: =AA36/AA37 -> 0.86129845 | AB38: =AB36/AB37 -> 0.86945368 | AC38: =AC36/AC37 -> 0.8983599
A42: FORD PEROLS | B42: 1 | C42: 2 | D42: 3 | E42: 4 | F42: 5 | G42: 6 | H42: 7 | I42: 8 | J42: 9 | K42: 10 | L42: 11 | M42: 12 | N42: 13 | O42: 14 | P42: 15 | Q42: 16 | R42: 17 | S42: 18 | T42: 19 | U42: 20 | V42: 21 | W42: 22 | X42: 23 | Y42: 24 | Z42: 25 | AA42: 26 | AB42: 27 | AC42: 28
A43: CA REALISE (CLIENT CESSION GARANTIE) | B43: 835 | C43: 1469 | F43: 1868 | G43: 2218 | H43: 2367 | I43: 3234 | J43: 4379 | M43: 5097 | N43: 5692 | O43: 6547 | P43: 7046 | Q43: 8774 | T43: 9518 | U43: 11717 | V43: 12350 | W43: 12552 | X43: 12854 | AA43: 13511 | AB43: 14115 | AC43: 14144
A44: OBJECTIF | B44: 731 | C44: =B44+731 -> 1462 | F44: =C44+731 -> 2193 | G44: =F44+731 -> 2924 | H44: =G44+731 -> 3655 | I44: =H44+731 -> 4386 | J44: =I44+731 -> 5117 | M44: =J44+731 -> 5848 | N44: =M44+731 -> 6579 | O44: =N44+731 -> 7310 | P44: =O44+731 -> 8041 | Q44: =P44+731 -> 8772 | T44: =Q44+731 -> 9503 | U44: =T44+731 -> 10234 | V44: =U44+731 -> 10965 | W44: =V44+731 -> 11696 | X44: =W44+731 -> 12427 | AA44: =X44+731 -> 13158 | AB44: =AA44+731 -> 13889 | AC44: =AB44+731 -> 14620
A45: % DE REALISATION | B45: =B43/B44 -> 1.1422709 | C45: =C43/C44 -> 1.004788 | F45: =F43/F44 -> 0.85180119 | G45: =G43/G44 -> 0.75854993 | H45: =H43/H44 -> 0.64760602 | I45: =I43/I44 -> 0.7373461 | J45: =J43/J44 -> 0.85577487 | M45: =M43/M44 -> 0.87158003 | N45: =N43/N44 -> 0.86517708 | O45: =O43/O44 -> 0.89562244 | P45: =P43/P44 -> 0.87625917 | Q45: =Q43/Q44 -> 1.000228 | T45: =T43/T44 -> 1.0015784 | U45: =U43/U44 -> 1.1449091 | V45: =V43/V44 -> 1.126311 | W45: =W43/W44 -> 1.0731874 | X45: =X43/X44 -> 1.0343607 | AA45: =AA43/AA44 -> 1.0268278 | AB45: =AB43/AB44 -> 1.0162719 | AC45: =AC43/AC44 -> 0.96744186
A48: SETE | B48: 1 | C48: 2 | D48: 3 | E48: 4 | F48: 5 | G48: 6 | H48: 7 | I48: 8 | J48: 9 | K48: 10 | L48: 11 | M48: 12 | N48: 13 | O48: 14 | P48: 15 | Q48: 16 | R48: 17 | S48: 18 | T48: 19 | U48: 20 | V48: 21 | W48: 22 | X48: 23 | Y48: 24 | Z48: 25 | AA48: 26 | AB48: 27 | AC48: 28
A49: CA REALISE (CLIENT CESSION GARANTIE) | B49: 726 | C49: 1857 | F49: 1918 | G49: 2301 | H49: 3250 | I49: 4003 | J49: 4659 | M49: 5166 | N49: 5430 | O49: 5531 | P49: 6294 | Q49: 6619 | T49: 6619 | U49: 7014 | V49: 7273 | W49: 7521 | X49: 7997.76 | AA49: 8478 | AB49: 9901 | AC49: 10454
A50: OBJECTIF | B50: 515 | C50: =B50+515 -> 1030 | F50: =C50+515 -> 1545 | G50: =F50+515 -> 2060 | H50: =G50+515 -> 2575 | I50: =H50+515 -> 3090 | J50: =I50+515 -> 3605 | M50: =J50+515 -> 4120 | N50: =M50+515 -> 4635 | O50: =N50+515 -> 5150 | P50: =O50+515 -> 5665 | Q50: =P50+515 -> 6180 | T50: =Q50+515 -> 6695 | U50: =T50+515 -> 7210 | V50: =U50+515 -> 7725 | W50: =V50+515 -> 8240 | X50: =W50+515 -> 8755 | AA50: =X50+515 -> 9270 | AB50: =AA50+515 -> 9785 | AC50: =AB50+515 -> 10300
A51: % DE REALISATION | B51: =B49/B50 -> 1.4097087 | C51: =C49/C50 -> 1.8029126 | F51: =F49/F50 -> 1.2414239 | G51: =G49/G50 -> 1.1169903 | H51: =H49/H50 -> 1.2621359 | I51: =I49/I50 -> 1.2954693 | J51: =J49/J50 -> 1.2923717 | M51: =M49/M50 -> 1.2538835 | N51: =N49/N50 -> 1.171521 | O51: =O49/O50 -> 1.0739806 | P51: =P49/P50 -> 1.1110327 | Q51: =Q49/Q50 -> 1.0710356 | T51: =T49/T50 -> 0.98864824 | U51: =U49/U50 -> 0.97281553 | V51: =V49/V50 -> 0.94148867 | W51: =W49/W50 -> 0.91274272 | X51: =X49/X50 -> 0.91350771 | AA51: =AA49/AA50 -> 0.91456311 | AB51: =AB49/AB50 -> 1.0118549 | AC51: =AC49/AC50 -> 1.0149515
A55: CARROSSERIE ST JEAN DE VEDAS | B55: 1 | C55: 2 | D55: 3 | E55: 4 | F55: 5 | G55: 6 | H55: 7 | I55: 8 | J55: 9 | K55: 10 | L55: 11 | M55: 12 | N55: 13 | O55: 14 | P55: 15 | Q55: 16 | R55: 17 | S55: 18 | T55: 19 | U55: 20 | V55: 21 | W55: 22 | X55: 23 | Y55: 24 | Z55: 25 | AA55: 26 | AB55: 27 | AC55: 28
A56: CA REALISE (CLIENT CESSION GARANTIE) | B56: 3641 | C56: 5231 | F56: 5764 | G56: 8701 | H56: 10894 | I56: 11516 | J56: 13696 | M56: 17359 | N56: 18768 | O56: 20252 | P56: 23997 | Q56: 25519 | T56: 26352 | U56: 28735 | V56: 30405 | W56: 35907 | X56: 38748.71 | AA56: 38909 | AB56: 42238 | AC56: 42203
A57: OBJECTIF | B57: 2004 | C57: =B57+2004 -> 4008 | F57: =C57+2004 -> 6012 | G57: =F57+2004 -> 8016 | H57: =G57+2004 -> 10020 | I57: =H57+2004 -> 12024 | J57: =I57+2004 -> 14028 | M57: =J57+2004 -> 16032 | N57: =M57+2004 -> 18036 | O57: =N57+2004 -> 20040 | P57: =O57+2004 -> 22044 | Q57: =P57+2004 -> 24048 | T57: =Q57+2004 -> 26052 | U57: =T57+2004 -> 28056 | V57: =U57+2004 -> 30060 | W57: =V57+2004 -> 32064 | X57: =W57+2004 -> 34068 | AA57: =X57+2004 -> 36072 | AB57: =AA57+2004 -> 38076 | AC57: =AB57+2004 -> 40080
A58: % DE REALISATION | B58: =B56/B57 -> 1.8168663 | C58: =C56/C57 -> 1.3051397 | F58: =F56/F57 -> 0.95874917 | G58: =G56/G57 -> 1.0854541 | H58: =H56/H57 -> 1.0872255 | I58: =I56/I57 -> 0.95775116 | J58: =J56/J57 -> 0.97633305 | M58: =M56/M57 -> 1.082772 | N58: =N56/N57 -> 1.0405855 | O58: =O56/O57 -> 1.0105788 | P58: =P56/P57 -> 1.0885955 | Q58: =Q56/Q57 -> 1.0611693 | T58: =T56/T57 -> 1.0115154 | U58: =U56/U57 -> 1.0242016 | V58: =V56/V57 -> 1.011477 | W58: =W56/W57 -> 1.119854 | X58: =X56/X57 -> 1.1373932 | AA58: =AA56/AA57 -> 1.0786483 | AB58: =AB56/AB57 -> 1.1093077 | AC58: =AC56/AC57 -> 1.0529691
A62: FORD RODEZ | B62: 1 | C62: 2 | D62: 3 | E62: 4 | F62: 5 | G62: 6 | H62: 7 | I62: 8 | J62: 9 | K62: 10 | L62: 11 | M62: 12 | N62: 13 | O62: 14 | P62: 15 | Q62: 16 | R62: 17 | S62: 18 | T62: 19 | U62: 20 | V62: 21 | W62: 22 | X62: 23 | Y62: 24 | Z62: 25 | AA62: 26 | AB62: 27 | AC62: 28
A63: CA REALISE (CLIENT CESSION GARANTIE) | B63: 516 | C63: 961 | F63: 1509 | G63: 2336 | H63: 3036 | I63: 4038 | J63: 4790 | M63: 5964 | N63: 6260 | O63: 7017 | P63: 7447 | Q63: 8047 | T63: 8465 | U63: 9183 | V63: 10385 | W63: 10920 | X63: 12549 | AA63: 13396 | AB63: 14267 | AC63: 18333
A64: OBJECTIF | B64: 913 | C64: =B64+913 -> 1826 | F64: =C64+913 -> 2739 | G64: =F64+913 -> 3652 | H64: =G64+913 -> 4565 | I64: =H64+913 -> 5478 | J64: =I64+913 -> 6391 | M64: =J64+913 -> 7304 | N64: =M64+913 -> 8217 | O64: =N64+913 -> 9130 | P64: =O64+913 -> 10043 | Q64: =P64+913 -> 10956 | T64: =Q64+913 -> 11869 | U64: =T64+913 -> 12782 | V64: =U64+913 -> 13695 | W64: =V64+913 -> 14608 | X64: =W64+913 -> 15521 | AA64: =X64+913 -> 16434 | AB64: =AA64+913 -> 17347 | AC64: =AB64+913 -> 18260
A65: % DE REALISATION | B65: =B63/B64 -> 0.56516977 | C65: =C63/C64 -> 0.52628697 | F65: =F63/F64 -> 0.550931 | G65: =G63/G64 -> 0.63964951 | H65: =H63/H64 -> 0.66506024 | I65: =I63/I64 -> 0.73713034 | J65: =J63/J64 -> 0.74949147 | M65: =M63/M64 -> 0.81653888 | N65: =N63/N64 -> 0.76183522 | O65: =O63/O64 -> 0.76856517 | P65: =P63/P64 -> 0.7415115 | Q65: =Q63/Q64 -> 0.73448339 | T65: =T63/T64 -> 0.71320246 | U65: =U63/U64 -> 0.71843217 | V65: =V63/V64 -> 0.75830595 | W65: =W63/W64 -> 0.7475356 | X65: =X63/X64 -> 0.80851749 | AA65: =AA63/AA64 -> 0.81513935 | AB65: =AB63/AB64 -> 0.82244769 | AC65: =AC63/AC64 -> 1.0039978
A69: LAND ROVER RODEZ | B69: 1 | C69: 2 | D69: 3 | E69: 4 | F69: 5 | G69: 6 | H69: 7 | I69: 8 | J69: 9 | K69: 10 | L69: 11 | M69: 12 | N69: 13 | O69: 14 | P69: 15 | Q69: 16 | R69: 17 | S69: 18 | T69: 19 | U69: 20 | V69: 21 | W69: 22 | X69: 23 | Y69: 24 | Z69: 25 | AA69: 26 | AB69: 27 | AC69: 28
...

Sheet Mars 2018
C1: Suivi objectif réalisation CA par atelier
AH4: =22 -> 22
S5: 5188
A7: GRIM PASSION LATTES | B7: 1 | C7: 2 | D7: 3 | E7: 4 | F7: 5 | G7: 6 | H7: 7 | I7: 8 | J7: 9 | K7: 10 | L7: 11 | M7: 12 | N7: 13 | O7: 14 | P7: 15 | Q7: 16 | R7: 17 | S7: 18 | T7: 19 | U7: 20 | V7: 21 | W7: 22 | X7: 23 | Y7: 24 | Z7: 25 | AA7: 26 | AB7: 27 | AC7: 28 | AD7: 29 | AE7: 30 | AF7: 31
A8: CA REALISE (CLIENT CESSION GARANTIE) | C8: 8652 | F8: 13629 | G8: 17502.93 | H8: 21001 | I8: 28685 | J8: 38014 | M8: 42088 | N8: 45781 | O8: 53489 | P8: 58112 | Q8: 63294 | T8: 69102 | U8: 74582 | V8: 83053 | W8: 89563 | X8: 95289 | AA8: 99526 | AB8: 102478 | AC8: 108493 | AD8: 114402 | AE8: 121927
A9: OBJECTIF | B9: 5856 | C9: =B9+5856 -> 11712 | F9: =C9+5856 -> 17568 | G9: =F9+5856 -> 23424 | H9: =G9+5856 -> 29280 | I9: =H9+5856 -> 35136 | J9: =I9+5856 -> 40992 | M9: =J9+5856 -> 46848 | N9: =M9+5856 -> 52704 | O9: =N9+5856 -> 58560 | P9: =O9+5856 -> 64416 | Q9: =P9+5856 -> 70272 | T9: =Q9+5856 -> 76128 | U9: =T9+5856 -> 81984 | V9: =U9+5856 -> 87840 | W9: =V9+5856 -> 93696 | X9: =W9+5856 -> 99552 | AA9: =X9+5856 -> 105408 | AB9: =AA9+5856 -> 111264 | AC9: =AB9+5856 -> 117120 | AD9: =AC9+5856 -> 122976 | AE9: =AD9+5856 -> 128832
A10: % DE REALISATION | B10: =B8/B9 -> 0 | C10: =C8/C9 -> 0.73872951 | F10: =F8/F9 -> 0.77578552 | G10: =G8/G9 -> 0.74722208 | H10: =H8/H9 -> 0.71724727 | I10: =I8/I9 -> 0.81639913 | J10: =J8/J9 -> 0.92735168 | M10: =M8/M9 -> 0.89839481 | N10: =N8/N9 -> 0.86864375 | O10: =O8/O9 -> 0.91340505 | P10: =P8/P9 -> 0.90213612 | Q10: =Q8/Q9 -> 0.90070014 | T10: =T8/T9 -> 0.90770807 | U10: =U8/U9 -> 0.90971409 | V10: =V8/V9 -> 0.94550319 | W10: =W8/W9 -> 0.95588926 | X10: =X8/X9 -> 0.95717816 | AA10: =AA8/AA9 -> 0.94419778 | AB10: =AB8/AB9 -> 0.92103466 | AC10: =AC8/AC9 -> 0.92634051 | AD10: =AD8/AD9 -> 0.93027908 | AE10: =AE8/AE9 -> 0.94640307
AH12: =AE9+AE16 -> 146256
A14: GRIM PASSION PEROLS | B14: 1 | C14: 2 | D14: 3 | E14: 4 | F14: 5 | G14: 6 | H14: 7 | I14: 8 | J14: 9 | K14: 10 | L14: 11 | M14: 12 | N14: 13 | O14: 14 | P14: 15 | Q14: 16 | R14: 17 | S14: 18 | T14: 19 | U14: 20 | V14: 21 | W14: 22 | X14: 23 | Y14: 24 | Z14: 25 | AA14: 26 | AB14: 27 | AC14: 28 | AD14: 29 | AE14: 30 | AF14: 31
A15: CA REALISE (CLIENT CESSION GARANTIE) | C15: 1745 | F15: 1804 | G15: 1804 | H15: 1804 | I15: 1804 | J15: 1822 | M15: 2391 | N15: 2673 | O15: 2673 | P15: 2673 | Q15: 3119 | T15: 3393 | U15: 4571 | V15: 5481 | W15: 5481 | X15: 6889 | AA15: 7484 | AB15: 7728 | AC15: 8565 | AD15: 8870 | AE15: 10558
A16: OBJECTIF | B16: 792 | C16: =B16+792 -> 1584 | F16: =C16+792 -> 2376 | G16: =F16+792 -> 3168 | H16: =G16+792 -> 3960 | I16: =H16+792 -> 4752 | J16: =I16+792 -> 5544 | M16: =J16+792 -> 6336 | N16: =M16+792 -> 7128 | O16: =N16+792 -> 7920 | P16: =O16+792 -> 8712 | Q16: =P16+792 -> 9504 | T16: =Q16+792 -> 10296 | U16: =T16+792 -> 11088 | V16: =U16+792 -> 11880 | W16: =V16+792 -> 12672 | X16: =W16+792 -> 13464 | AA16: =X16+792 -> 14256 | AB16: =AA16+792 -> 15048 | AC16: =AB16+792 -> 15840 | AD16: =AC16+792 -> 16632 | AE16: =AD16+792 -> 17424
A17: % DE REALISATION | B17: =B15/B16 -> 0 | C17: =C15/C16 -> 1.1016414 | F17: =F15/F16 -> 0.75925926 | G17: =G15/G16 -> 0.56944444 | H17: =H15/H16 -> 0.45555556 | I17: =I15/I16 -> 0.37962963 | J17: =J15/J16 -> 0.32864358 | M17: =M15/M16 -> 0.37736742 | N17: =N15/N16 -> 0.375 | O17: =O15/O16 -> 0.3375 | P17: =P15/P16 -> 0.30681818 | Q17: =Q15/Q16 -> 0.32817761 | T17: =T15/T16 -> 0.32954545 | U17: =U15/U16 -> 0.41224747 | V17: =V15/V16 -> 0.46136364 | W17: =W15/W16 -> 0.43252841 | X17: =X15/X16 -> 0.51166072 | AA17: =AA15/AA16 -> 0.52497194 | AB17: =AB15/AB16 -> 0.51355662 | AC17: =AC15/AC16 -> 0.5407197 | AD17: =AD15/AD16 -> 0.53330928 | AE17: =AE15/AE16 -> 0.60594582
A21: PRESTIGE AUTO MONTPELLIER | B21: 1 | C21: 2 | D21: 3 | E21: 4 | F21: 5 | G21: 6 | H21: 7 | I21: 8 | J21: 9 | K21: 10 | L21: 11 | M21: 12 | N21: 13 | O21: 14 | P21: 15 | Q21: 16 | R21: 17 | S21: 18 | T21: 19 | U21: 20 | V21: 21 | W21: 22 | X21: 23 | Y21: 24 | Z21: 25 | AA21: 26 | AB21: 27 | AC21: 28 | AD21: 29 | AE21: 30 | AF21: 31
A22: CA REALISE (CLIENT CESSION GARANTIE) | C22: 7053 | F22: 8603 | G22: 9148 | H22: 11153 | I22: 14138 | J22: 15279 | M22: 17136 | N22: 17655 | O22: 19550 | P22: 21260 | Q22: 24295 | T22: 25169 | U22: 31515 | V22: 31854 | W22: 33666 | X22: 37024 | AA22: 39173 | AB22: 41819 | AC22: 45422 | AD22: 46777 | AE22: 53101
A23: OBJECTIF | B23: 2877 | C23: =B23+2877 -> 5754 | F23: =C23+2877 -> 8631 | G23: =F23+2877 -> 11508 | H23: =G23+2877 -> 14385 | I23: =H23+2877 -> 17262 | J23: =I23+2877 -> 20139 | M23: =J23+2877 -> 23016 | N23: =M23+2877 -> 25893 | O23: =N23+2877 -> 28770 | P23: =O23+2877 -> 31647 | Q23: =P23+2877 -> 34524 | T23: =Q23+2877 -> 37401 | U23: =T23+2877 -> 40278 | V23: =U23+2877 -> 43155 | W23: =V23+2877 -> 46032 | X23: =W23+2877 -> 48909 | AA23: =X23+2877 -> 51786 | AB23: =AA23+2877 -> 54663 | AC23: =AB23+2877 -> 57540 | AD23: =AC23+2877 -> 60417 | AE23: =AD23+2877 -> 63294
A24: % DE REALISATION | B24: =B22/B23 -> 0 | C24: =C22/C23 -> 1.225756 | F24: =F22/F23 -> 0.99675588 | G24: =G22/G23 -> 0.79492527 | H24: =H22/H23 -> 0.77532152 | I24: =I22/I23 -> 0.81902445 | J24: =J22/J23 -> 0.75867719 | M24: =M22/M23 -> 0.74452555 | N24: =N22/N23 -> 0.68184451 | O24: =O22/O23 -> 0.67952729 | P24: =P22/P23 -> 0.67178564 | Q24: =Q22/Q23 -> 0.70371336 | T24: =T22/T23 -> 0.67294992 | U24: =U22/U23 -> 0.78243706 | V24: =V22/V23 -> 0.73813 | W24: =W22/W23 -> 0.73136079 | X24: =X22/X23 -> 0.75699769 | AA24: =AA22/AA23 -> 0.75643996 | AB24: =AB22/AB23 -> 0.76503302 | AC24: =AC22/AC23 -> 0.78939868 | AD24: =AD22/AD23 -> 0.77423573 | AE24: =AE22/AE23 -> 0.83895788
A28: PRESTIGE AUTO NIMES | B28: 1 | C28: 2 | D28: 3 | E28: 4 | F28: 5 | G28: 6 | H28: 7 | I28: 8 | J28: 9 | K28: 10 | L28: 11 | M28: 12 | N28: 13 | O28: 14 | P28: 15 | Q28: 16 | R28: 17 | S28: 18 | T28: 19 | U28: 20 | V28: 21 | W28: 22 | X28: 23 | Y28: 24 | Z28: 25 | AA28: 26 | AB28: 27 | AC28: 28 | AD28: 29 | AE28: 30 | AF28: 31
A29: CA REALISE (CLIENT CESSION GARANTIE) | C29: 2605 | F29: 3495 | G29: 4523 | H29: 5851 | I29: 6630 | J29: 7235 | M29: 8013 | N29: 10852 | O29: 10948 | P29: 13742 | Q29: 14974 | T29: 17094 | U29: 17515 | V29: 18789 | W29: 18915 | X29: 20754 | AA29: 22058 | AB29: 25262 | AC29: 27078 | AD29: 29161 | AE29: 33339
A30: OBJECTIF | B30: 1770 | C30: =B30+1770 -> 3540 | F30: =C30+1770 -> 5310 | G30: =F30+1770 -> 7080 | H30: =G30+1770 -> 8850 | I30: =H30+1770 -> 10620 | J30: =I30+1770 -> 12390 | M30: =J30+1770 -> 14160 | N30: =M30+1770 -> 15930 | O30: =N30+1770 -> 17700 | P30: =O30+1770 -> 19470 | Q30: =P30+1770 -> 21240 | T30: =Q30+1770 -> 23010 | U30: =T30+1770 -> 24780 | V30: =U30+1770 -> 26550 | W30: =V30+1770 -> 28320 | X30: =W30+1770 -> 30090 | AA30: =X30+1770 -> 31860 | AB30: =AA30+1770 -> 33630 | AC30: =AB30+1770 -> 35400 | AD30: =AC30+1770 -> 37170 | AE30: =AD30+1770 -> 38940
A31: % DE REALISATION | B31: =B29/B30 -> 0 | C31: =C29/C30 -> 0.73587571 | F31: =F29/F30 -> 0.65819209 | G31: =G29/G30 -> 0.63884181 | H31: =H29/H30 -> 0.66112994 | I31: =I29/I30 -> 0.62429379 | J31: =J29/J30 -> 0.58393866 | M31: =M29/M30 -> 0.56588983 | N31: =N29/N30 -> 0.68123038 | O31: =O29/O30 -> 0.61853107 | P31: =P29/P30 -> 0.7058038 | Q31: =Q29/Q30 -> 0.70499058 | T31: =T29/T30 -> 0.74289439 | U31: =U29/U30 -> 0.70682002 | V31: =V29/V30 -> 0.70768362 | W31: =W29/W30 -> 0.66790254 | X31: =X29/X30 -> 0.68973081 | AA31: =AA29/AA30 -> 0.69234149 | AB31: =AB29/AB30 -> 0.75117455 | AC31: =AC29/AC30 -> 0.76491525 | AD31: =AD29/AD30 -> 0.78453054 | AE31: =AE29/AE30 -> 0.85616333
A35: FORD LATTES | B35: 1 | C35: 2 | D35: 3 | E35: 4 | F35: 5 | G35: 6 | H35: 7 | I35: 8 | J35: 9 | K35: 10 | L35: 11 | M35: 12 | N35: 13 | O35: 14 | P35: 15 | Q35: 16 | R35: 17 | S35: 18 | T35: 19 | U35: 20 | V35: 21 | W35: 22 | X35: 23 | Y35: 24 | Z35: 25 | AA35: 26 | AB35: 27 | AC35: 28 | AD35: 29 | AE35: 30 | AF35: 31
A36: CA REALISE (CLIENT CESSION GARANTIE) | C36: 1137 | F36: 2789 | G36: 6736 | H36: 8243 | I36: 9196 | J36: 12165 | M36: 14655 | N36: 19372 | O36: 21485 | P36: 22728 | Q36: 27013 | T36: 30884 | U36: 32886 | V36: 37137 | W36: 40588 | X36: 43591 | AA36: 45432 | AB36: 48972 | AC36: 53311 | AD36: 55604 | AE36: 60653
A37: OBJECTIF | B37: 3262 | C37: =B37+3262 -> 6524 | F37: =C37+3262 -> 9786 | G37: =F37+3262 -> 13048 | H37: =G37+3262 -> 16310 | I37: =H37+3262 -> 19572 | J37: =I37+3262 -> 22834 | M37: =J37+3262 -> 26096 | N37: =M37+3262 -> 29358 | O37: =N37+3262 -> 32620 | P37: =O37+3262 -> 35882 | Q37: =P37+3262 -> 39144 | T37: =Q37+3262 -> 42406 | U37: =T37+3262 -> 45668 | V37: =U37+3262 -> 48930 | W37: =V37+3262 -> 52192 | X37: =W37+3262 -> 55454 | AA37: =X37+3262 -> 58716 | AB37: =AA37+3262 -> 61978 | AC37: =AB37+3262 -> 65240 | AD37: =AC37+3262 -> 68502 | AE37: =AD37+3262 -> 71764
A38: % DE REALISATION | B38: =B36/B37 -> 0 | C38: =C36/C37 -> 0.17427958 | F38: =F36/F37 -> 0.28499898 | G38: =G36/G37 -> 0.5162477 | H38: =H36/H37 -> 0.50539546 | I38: =I36/I37 -> 0.46985489 | J38: =J36/J37 -> 0.53275817 | M38: =M36/M37 -> 0.56158032 | N38: =N36/N37 -> 0.65985421 | O38: =O36/O37 -> 0.658645 | P38: =P36/P37 -> 0.63340951 | Q38: =Q36/Q37 -> 0.69009299 | T38: =T36/T37 -> 0.72829317 | U38: =U36/U37 -> 0.72011036 | V38: =V36/V37 -> 0.75898222 | W38: =W36/W37 -> 0.77766708 | X38: =X36/X37 -> 0.78607494 | AA38: =AA36/AA37 -> 0.77375843 | AB38: =AB36/AB37 -> 0.79015134 | AC38: =AC36/AC37 -> 0.81715205 | AD38: =AD36/AD37 -> 0.81171353 | AE38: =AE36/AE37 -> 0.84517307
A42: FORD PEROLS | B42: 1 | C42: 2 | D42: 3 | E42: 4 | F42: 5 | G42: 6 | H42: 7 | I42: 8 | J42: 9 | K42: 10 | L42: 11 | M42: 12 | N42: 13 | O42: 14 | P42: 15 | Q42: 16 | R42: 17 | S42: 18 | T42: 19 | U42: 20 | V42: 21 | W42: 22 | X42: 23 | Y42: 24 | Z42: 25 | AA42: 26 | AB42: 27 | AC42: 28 | AD42: 29 | AE42: 30 | AF42: 31
A43: CA REALISE (CLIENT CESSION GARANTIE) | C43: 360 | F43: 773 | G43: 1426 | H43: 1553 | I43: 3115 | J43: 3557 | M43: 4123 | N43: 5018 | O43: 5176 | P43: 5647 | Q43: 6391 | T43: 6561 | U43: 6902 | V43: 7598 | W43: 9104 | X43: 9828 | AA43: 10220 | AB43: 10546 | AC43: 10546 | AD43: 11199 | AE43: 13210
A44: OBJECTIF | B44: =731 -> 731 | C44: =B44+731 -> 1462 | F44: =C44+731 -> 2193 | G44: =F44+731 -> 2924 | H44: =G44+731 -> 3655 | I44: =H44+731 -> 4386 | J44: =I44+731 -> 5117 | M44: =J44+731 -> 5848 | N44: =M44+731 -> 6579 | O44: =N44+731 -> 7310 | P44: =O44+731 -> 8041 | Q44: =P44+731 -> 8772 | T44: =Q44+731 -> 9503 | U44: =T44+731 -> 10234 | V44: =U44+731 -> 10965 | W44: =V44+731 -> 11696 | X44: =W44+731 -> 12427 | AA44: =X44+731 -> 13158 | AB44: =AA44+731 -> 13889 | AC44: =AB44+731 -> 14620 | AD44: =AC44+731 -> 15351 | AE44: =AD44+731 -> 16082
A45: % DE REALISATION | B45: =B43/B44 -> 0 | C45: =C43/C44 -> 0.24623803 | F45: =F43/F44 -> 0.35248518 | G45: =G43/G44 -> 0.4876881 | H45: =H43/H44 -> 0.4248974 | I45: =I43/I44 -> 0.71021432 | J45: =J43/J44 -> 0.69513387 | M45: =M43/M44 -> 0.70502736 | N45: =N43/N44 -> 0.7627299 | O45: =O43/O44 -> 0.70807114 | P45: =P43/P44 -> 0.70227584 | Q45: =Q43/Q44 -> 0.72856817 | T45: =T43/T44 -> 0.69041355 | U45: =U43/U44 -> 0.6744186 | V45: =V43/V44 -> 0.69293206 | W45: =W43/W44 -> 0.77838577 | X45: =X43/X44 -> 0.79085861 | AA45: =AA43/AA44 -> 0.77671379 | AB45: =AB43/AB44 -> 0.75930593 | AC45: =AC43/AC44 -> 0.72134063 | AD45: =AD43/AD44 -> 0.72952902 | AE45: =AE43/AE44 -> 0.82141525
A48: SETE | B48: 1 | C48: 2 | D48: 3 | E48: 4 | F48: 5 | G48: 6 | H48: 7 | I48: 8 | J48: 9 | K48: 10 | L48: 11 | M48: 12 | N48: 13 | O48: 14 | P48: 15 | Q48: 16 | R48: 17 | S48: 18 | T48: 19 | U48: 20 | V48: 21 | W48: 22 | X48: 23 | Y48: 24 | Z48: 25 | AA48: 26 | AB48: 27 | AC48: 28 | AD48: 29 | AE48: 30 | AF48: 31
A49: CA REALISE (CLIENT CESSION GARANTIE) | C49: 624 | F49: 1256 | G49: 1288 | H49: 1438 | I49: 1846 | J49: 2574 | M49: 2908 | N49: 3461 | O49: 3824 | P49: 3872 | Q49: 5863 | T49: 6032 | U49: 6251 | V49: 6334 | W49: 6930 | X49: 7106 | AA49: 7300 | AB49: 7649 | AC49: 8042 | AD49: 8475 | AE49: 8879
A50: OBJECTIF | B50: 515 | C50: =B50+515 -> 1030 | F50: =C50+515 -> 1545 | G50: =F50+515 -> 2060 | H50: =G50+515 -> 2575 | I50: =H50+515 -> 3090 | J50: =I50+515 -> 3605 | M50: =J50+515 -> 4120 | N50: =M50+515 -> 4635 | O50: =N50+515 -> 5150 | P50: =O50+515 -> 5665 | Q50: =P50+515 -> 6180 | T50: =Q50+515 -> 6695 | U50: =T50+515 -> 7210 | V50: =U50+515 -> 7725 | W50: =V50+515 -> 8240 | X50: =W50+515 -> 8755 | AA50: =X50+515 -> 9270 | AB50: =AA50+515 -> 9785 | AC50: =AB50+515 -> 10300 | AD50: =AC50+515 -> 10815 | AE50: =AD50+515 -> 11330
A51: % DE REALISATION | B51: =B49/B50 -> 0 | C51: =C49/C50 -> 0.60582524 | F51: =F49/F50 -> 0.81294498 | G51: =G49/G50 -> 0.62524272 | H51: =H49/H50 -> 0.5584466 | I51: =I49/I50 -> 0.597411 | J51: =J49/J50 -> 0.71400832 | M51: =M49/M50 -> 0.70582524 | N51: =N49/N50 -> 0.74670982 | O51: =O49/O50 -> 0.74252427 | P51: =P49/P50 -> 0.68349515 | Q51: =Q49/Q50 -> 0.9487055 | T51: =T49/T50 -> 0.90097087 | U51: =U49/U50 -> 0.86699029 | V51: =V49/V50 -> 0.81993528 | W51: =W49/W50 -> 0.84101942 | X51: =X49/X50 -> 0.81165049 | AA51: =AA49/AA50 -> 0.78748652 | AB51: =AB49/AB50 -> 0.78170669 | AC51: =AC49/AC50 -> 0.7807767 | AD51: =AD49/AD50 -> 0.78363384 | AE51: =AE49/AE50 -> 0.78367167
A55: CARROSSERIE ST JEAN DE VEDAS | B55: 1 | C55: 2 | D55: 3 | E55: 4 | F55: 5 | G55: 6 | H55: 7 | I55: 8 | J55: 9 | K55: 10 | L55: 11 | M55: 12 | N55: 13 | O55: 14 | P55: 15 | Q55: 16 | R55: 17 | S55: 18 | T55: 19 | U55: 20 | V55: 21 | W55: 22 | X55: 23 | Y55: 24 | Z55: 25 | AA55: 26 | AB55: 27 | AC55: 28 | AD55: 29 | AE55: 30 | AF55: 31
A56: CA REALISE (CLIENT CESSION GARANTIE) | C56: 4522 | F56: 8628 | G56: 8884 | H56: 14271 | I56: 15733 | J56: 17990 | M56: 19231 | N56: 22031 | O56: 23333 | P56: 30292 | Q56: 33202 | T56: 35233 | U56: 37951 | V56: 39401 | W56: 39747 | X56: 44791 | AA56: 45259 | AB56: 47890 | AC56: 48944 | AD56: 50531 | AE56: 56837
A57: OBJECTIF | B57: 2004 | C57: =B57+2004 -> 4008 | F57: =C57+2004 -> 6012 | G57: =F57+2004 -> 8016 | H57: =G57+2004 -> 10020 | I57: =H57+2004 -> 12024 | J57: =I57+2004 -> 14028 | M57: =J57+2004 -> 16032 | N57: =M57+2004 -> 18036 | O57: =N57+2004 -> 20040 | P57: =O57+2004 -> 22044 | Q57: =P57+2004 -> 24048 | T57: =Q57+2004 -> 26052 | U57: =T57+2004 -> 28056 | V57: =U57+2004 -> 30060 | W57: =V57+2004 -> 32064 | X57: =W57+2004 -> 34068 | AA57: =X57+2004 -> 36072 | AB57: =AA57+2004 -> 38076 | AC57: =AB57+2004 -> 40080 | AD57: =AC57+2004 -> 42084 | AE57: =AD57+2004 -> 44088
A58: % DE REALISATION | B58: =B56/B57 -> 0 | C58: =C56/C57 -> 1.1282435 | F58: =F56/F57 -> 1.4351297 | G58: =G56/G57 -> 1.1082834 | H58: =H56/H57 -> 1.4242515 | I58: =I56/I57 -> 1.3084664 | J58: =J56/J57 -> 1.2824351 | M58: =M56/M57 -> 1.1995384 | N58: =N56/N57 -> 1.2215014 | O58: =O56/O57 -> 1.1643214 | P58: =P56/P57 -> 1.3741608 | Q58: =Q56/Q57 -> 1.3806554 | T58: =T56/T57 -> 1.3524106 | U58: =U56/U57 -> 1.3526875 | V58: =V56/V57 -> 1.3107452 | W58: =W56/W57 -> 1.2396145 | X58: =X56/X57 -> 1.3147528 | AA58: =AA56/AA57 -> 1.2546851 | AB58: =AB56/AB57 -> 1.2577477 | AC58: =AC56/AC57 -> 1.2211577 | AD58: =AD56/AD57 -> 1.2007176 | AE58: =AE56/AE57 -> 1.2891717
A62: FORD RODEZ | B62: 1 | C62: 2 | D62: 3 | E62: 4 | F62: 5 | G62: 6 | H62: 7 | I62: 8 | J62: 9 | K62: 10 | L62: 11 | M62: 12 | N62: 13 | O62: 14 | P62: 15 | Q62: 16 | R62: 17 | S62: 18 | T62: 19 | U62: 20 | V62: 21 | W62: 22 | X62: 23 | Y62: 24 | Z62: 25 | AA62: 26 | AB62: 27 | AC62: 28 | AD62: 29 | AE62: 30 | AF62: 31
A63: CA REALISE (CLIENT CESSION GARANTIE) | C63: 762 | F63: 1267 | G63: 1557 | H63: 2895 | I63: 3194 | J63: 4964 | M63: 5648 | N63: 6089 | O63: 6491 | P63: 7750 | Q63: 8389 | T63: 10125 | U63: 11329 | V63: 11695 | W63: 12711 | X63: 13765 | AA63: 14207 | AB63: 15160 | AC63: 16121 | AD63: 18147 | AE63: 20329
A64: OBJECTIF | B64: 913 | C64: =B64+913 -> 1826 | F64: =C64+913 -> 2739 | G64: =F64+913 -> 3652 | H64: =G64+913 -> 4565 | I64: =H64+913 -> 5478 | J64: =I64+913 -> 6391 | M64: =J64+913 -> 7304 | N64: =M64+913 -> 8217 | O64: =N64+913 -> 9130 | P64: =O64+913 -> 10043 | Q64: =P64+913 -> 10956 | T64: =Q64+913 -> 11869 | U64: =T64+913 -> 12782 | V64: =U64+913 -> 13695 | W64: =V64+913 -> 14608 | X64: =W64+913 -> 15521 | AA64: =X64+913 -> 16434 | AB64: =AA64+913 -> 17347 | AC64: =AB64+913 -> 18260 | AD64: =AC64+913 -> 19173 | AE64: =AD64+913 -> 20086
A65: % DE REALISATION | B65: =B63/B64 -> 0 | C65: =C63/C64 -> 0.41730559 | F65: =F63/F64 -> 0.46257758 | G65: =G63/G64 -> 0.42634173 | H65: =H63/H64 -> 0.63417306 | I65: =I63/I64 -> 0.58305951 | J65: =J63/J64 -> 0.77671726 | M65: =M63/M64 -> 0.77327492 | N65: =N63/N64 -> 0.7410247 | O65: =O63/O64 -> 0.7109529 | P65: =P63/P64 -> 0.77168177 | Q65: =Q63/Q64 -> 0.76569916 | T65: =T63/T64 -> 0.8530626 | U65: =U63/U64 -> 0.88632452 | V65: =V63/V64 -> 0.8539613 | W65: =W63/W64 -> 0.87013965 | X65: =X63/X64 -> 0.88686296 | AA65: =AA63/AA64 -> 0.86448826 | AB65: =AB63/AB64 -> 0.87392633 | AC65: =AC63/AC64 -> 0.88285871 | AD65: =AD63/AD64 -> 0.94648725 | AE65: =AE63/AE64 -> 1.012098
...

Sheet Avril 2018
C1: Suivi objectif réalisation CA par atelier
AG4: =20 -> 20
S5: 5188
A7: GRIM PASSION LATTES | B7: 1 | C7: 2 | D7: 3 | E7: 4 | F7: 5 | G7: 6 | H7: 7 | I7: 8 | J7: 9 | K7: 10 | L7: 11 | M7: 12 | N7: 13 | O7: 14 | P7: 15 | Q7: 16 | R7: 17 | S7: 18 | T7: 19 | U7: 20 | V7: 21 | W7: 22 | X7: 23 | Y7: 24 | Z7: 25 | AA7: 26 | AB7: 27 | AC7: 28 | AD7: 29 | AE7: 30
A8: CA REALISE (CLIENT CESSION GARANTIE) | D8: 2238 | E8: 5736 | F8: 10190 | G8: 18258 | J8: 20592 | K8: 24163 | L8: 28956 | M8: 33419 | N8: 37928 | Q8: 41756 | R8: 44194 | S8: 52055 | T8: 55647 | U8: 65765 | X8: 68856 | Y8: 73063 | Z8: 78282 | AA8: 82656 | AB8: 86731 | AE8: 89510
A9: OBJECTIF | D9: 5856 | E9: =D9+5856 -> 11712 | F9: =E9+5856 -> 17568 | G9: =F9+5856 -> 23424 | J9: =G9+5856 -> 29280 | K9: =J9+5856 -> 35136 | L9: =K9+5856 -> 40992 | M9: =L9+5856 -> 46848 | N9: =M9+5856 -> 52704 | Q9: =N9+5856 -> 58560 | R9: =Q9+5856 -> 64416 | S9: =R9+5856 -> 70272 | T9: =S9+5856 -> 76128 | U9: =T9+5856 -> 81984 | X9: =U9+5856 -> 87840 | Y9: =X9+5856 -> 93696 | Z9: =Y9+5856 -> 99552 | AA9: =Z9+5856 -> 105408 | AB9: =AA9+5856 -> 111264 | AE9: =AB9+5856 -> 117120
A10: % DE REALISATION | D10: =D8/D9 -> 0.38217213 | E10: =E8/E9 -> 0.4897541 | F10: =F8/F9 -> 0.58003188 | G10: =G8/G9 -> 0.77945697 | J10: =J8/J9 -> 0.70327869 | K10: =K8/K9 -> 0.68769923 | L10: =L8/L9 -> 0.70638173 | M10: =M8/M9 -> 0.71334956 | N10: =N8/N9 -> 0.71964177 | Q10: =Q8/Q9 -> 0.71304645 | R10: =R8/R9 -> 0.68607178 | S10: =S8/S9 -> 0.74076446 | T10: =T8/T9 -> 0.73096627 | U10: =U8/U9 -> 0.80216872 | X10: =X8/X9 -> 0.78387978 | Y10: =Y8/Y9 -> 0.77978782 | Z10: =Z8/Z9 -> 0.78634282 | AA10: =AA8/AA9 -> 0.78415301 | AB10: =AB8/AB9 -> 0.7795064 | AE10: =AE8/AE9 -> 0.76425888
A14: GRIM PASSION PEROLS | B14: 1 | C14: 2 | D14: 3 | E14: 4 | F14: 5 | G14: 6 | H14: 7 | I14: 8 | J14: 9 | K14: 10 | L14: 11 | M14: 12 | N14: 13 | O14: 14 | P14: 15 | Q14: 16 | R14: 17 | S14: 18 | T14: 19 | U14: 20 | V14: 21 | W14: 22 | X14: 23 | Y14: 24 | Z14: 25 | AA14: 26 | AB14: 27 | AC14: 28 | AD14: 29 | AE14: 30
A15: CA REALISE (CLIENT CESSION GARANTIE) | D15: 0 | E15: 288 | F15: 1507 | G15: 2498 | J15: 2832 | K15: 3368 | L15: 4000 | M15: 5495 | N15: 5720 | Q15: 6260 | R15: 6338 | S15: 6338 | T15: 6338 | U15: 6338 | X15: 7808 | Y15: 9521 | Z15: 10744 | AA15: 13509 | AB15: 14243 | AE15: 16831
A16: OBJECTIF | D16: 792 | E16: =D16+792 -> 1584 | F16: =E16+792 -> 2376 | G16: =F16+792 -> 3168 | J16: =G16+792 -> 3960 | K16: =J16+792 -> 4752 | L16: =K16+792 -> 5544 | M16: =L16+792 -> 6336 | N16: =M16+792 -> 7128 | Q16: =N16+792 -> 7920 | R16: =Q16+792 -> 8712 | S16: =R16+792 -> 9504 | T16: =S16+792 -> 10296 | U16: =T16+792 -> 11088 | X16: =U16+792 -> 11880 | Y16: =X16+792 -> 12672 | Z16: =Y16+792 -> 13464 | AA16: =Z16+792 -> 14256 | AB16: =AA16+792 -> 15048 | AE16: =AB16+792 -> 15840
A17: % DE REALISATION | D17: =D15/D16 -> 0 | E17: =E15/E16 -> 0.18181818 | F17: =F15/F16 -> 0.63425926 | G17: =G15/G16 -> 0.7885101 | J17: =J15/J16 -> 0.71515152 | K17: =K15/K16 -> 0.70875421 | L17: =L15/L16 -> 0.72150072 | M17: =M15/M16 -> 0.86726641 | N17: =N15/N16 -> 0.80246914 | Q17: =Q15/Q16 -> 0.79040404 | R17: =R15/R16 -> 0.7275023 | S17: =S15/S16 -> 0.6668771 | T17: =T15/T16 -> 0.61557887 | U17: =U15/U16 -> 0.57160895 | X17: =X15/X16 -> 0.65723906 | Y17: =Y15/Y16 -> 0.75134154 | Z17: =Z15/Z16 -> 0.7979798 | AA17: =AA15/AA16 -> 0.94760101 | AB17: =AB15/AB16 -> 0.94650452 | AE17: =AE15/AE16 -> 1.0625631
A21: PRESTIGE AUTO MONTPELLIER | B21: 1 | C21: 2 | D21: 3 | E21: 4 | F21: 5 | G21: 6 | H21: 7 | I21: 8 | J21: 9 | K21: 10 | L21: 11 | M21: 12 | N21: 13 | O21: 14 | P21: 15 | Q21: 16 | R21: 17 | S21: 18 | T21: 19 | U21: 20 | V21: 21 | W21: 22 | X21: 23 | Y21: 24 | Z21: 25 | AA21: 26 | AB21: 27 | AC21: 28 | AD21: 29 | AE21: 30
A22: CA REALISE (CLIENT CESSION GARANTIE) | D22: 1801 | E22: 2775 | F22: 4287 | G22: 10121 | J22: 12860 | K22: 14955 | L22: 17577 | M22: 21260 | N22: 24642 | Q22: 25617 | R22: 27530 | S22: 31125 | T22: 32861 | U22: 34910 | X22: 36085 | Y22: 37493 | Z22: 41220 | AA22: 43659 | AB22: 49343 | AE22: 52844
A23: OBJECTIF | D23: 2877 | E23: =D23+2877 -> 5754 | F23: =E23+2877 -> 8631 | G23: =F23+2877 -> 11508 | J23: =G23+2877 -> 14385 | K23: =J23+2877 -> 17262 | L23: =K23+2877 -> 20139 | M23: =L23+2877 -> 23016 | N23: =M23+2877 -> 25893 | Q23: =N23+2877 -> 28770 | R23: =Q23+2877 -> 31647 | S23: =R23+2877 -> 34524 | T23: =S23+2877 -> 37401 | U23: =T23+2877 -> 40278 | X23: =U23+2877 -> 43155 | Y23: =X23+2877 -> 46032 | Z23: =Y23+2877 -> 48909 | AA23: =Z23+2877 -> 51786 | AB23: =AA23+2877 -> 54663 | AE23: =AB23+2877 -> 57540
A24: % DE REALISATION | D24: =D22/D23 -> 0.6259993 | E24: =E22/E23 -> 0.4822732 | F24: =F22/F23 -> 0.49669795 | G24: =G22/G23 -> 0.87947515 | J24: =J22/J23 -> 0.89398679 | K24: =K22/K23 -> 0.86635384 | L24: =L22/L23 -> 0.87278415 | M24: =M22/M23 -> 0.92370525 | N24: =N22/N23 -> 0.95168578 | Q24: =Q22/Q23 -> 0.89040667 | R24: =R22/R23 -> 0.86990868 | S24: =S22/S23 -> 0.90154675 | T24: =T22/T23 -> 0.87861287 | U24: =U22/U23 -> 0.86672625 | X24: =X22/X23 -> 0.83617194 | Y24: =Y22/Y23 -> 0.81449861 | Z24: =Z22/Z23 -> 0.84278967 | AA24: =AA22/AA23 -> 0.84306569 | AB24: =AB22/AB23 -> 0.9026764 | AE24: =AE22/AE23 -> 0.91838721
A28: PRESTIGE AUTO NIMES | B28: 1 | C28: 2 | D28: 3 | E28: 4 | F28: 5 | G28: 6 | H28: 7 | I28: 8 | J28: 9 | K28: 10 | L28: 11 | M28: 12 | N28: 13 | O28: 14 | P28: 15 | Q28: 16 | R28: 17 | S28: 18 | T28: 19 | U28: 20 | V28: 21 | W28: 22 | X28: 23 | Y28: 24 | Z28: 25 | AA28: 26 | AB28: 27 | AC28: 28 | AD28: 29 | AE28: 30
A29: CA REALISE (CLIENT CESSION GARANTIE) | D29: 1230 | E29: 2109 | F29: 2488 | G29: 4598 | J29: 5167 | K29: 5852 | L29: 6620 | M29: 7266 | N29: 9204 | Q29: 10972 | R29: 13149 | S29: 13581 | T29: 14240 | U29: 16534 | X29: 18028 | Y29: 20613 | Z29: 21633 | AA29: 23275 | AB29: 26228 | AE29: 30687
A30: OBJECTIF | D30: 1770 | E30: =D30+1770 -> 3540 | F30: =E30+1770 -> 5310 | G30: =F30+1770 -> 7080 | J30: =G30+1770 -> 8850 | K30: =J30+1770 -> 10620 | L30: =K30+1770 -> 12390 | M30: =L30+1770 -> 14160 | N30: =M30+1770 -> 15930 | Q30: =N30+1770 -> 17700 | R30: =Q30+1770 -> 19470 | S30: =R30+1770 -> 21240 | T30: =S30+1770 -> 23010 | U30: =T30+1770 -> 24780 | X30: =U30+1770 -> 26550 | Y30: =X30+1770 -> 28320 | Z30: =Y30+1770 -> 30090 | AA30: =Z30+1770 -> 31860 | AB30: =AA30+1770 -> 33630 | AE30: =AB30+1770 -> 35400
A31: % DE REALISATION | D31: =D29/D30 -> 0.69491525 | E31: =E29/E30 -> 0.59576271 | F31: =F29/F30 -> 0.46854991 | G31: =G29/G30 -> 0.64943503 | J31: =J29/J30 -> 0.58384181 | K31: =K29/K30 -> 0.55103578 | L31: =L29/L30 -> 0.53430186 | M31: =M29/M30 -> 0.51313559 | N31: =N29/N30 -> 0.57777778 | Q31: =Q29/Q30 -> 0.61988701 | R31: =R29/R30 -> 0.67534669 | S31: =S29/S30 -> 0.63940678 | T31: =T29/T30 -> 0.61886136 | U31: =U29/U30 -> 0.66723164 | X31: =X29/X30 -> 0.67902072 | Y31: =Y29/Y30 -> 0.72786017 | Z31: =Z29/Z30 -> 0.71894317 | AA31: =AA29/AA30 -> 0.73053986 | AB31: =AB29/AB30 -> 0.7798989 | AE31: =AE29/AE30 -> 0.86686441
A35: FORD LATTES | B35: 1 | C35: 2 | D35: 3 | E35: 4 | F35: 5 | G35: 6 | H35: 7 | I35: 8 | J35: 9 | K35: 10 | L35: 11 | M35: 12 | N35: 13 | O35: 14 | P35: 15 | Q35: 16 | R35: 17 | S35: 18 | T35: 19 | U35: 20 | V35: 21 | W35: 22 | X35: 23 | Y35: 24 | Z35: 25 | AA35: 26 | AB35: 27 | AC35: 28 | AD35: 29 | AE35: 30
A36: CA REALISE (CLIENT CESSION GARANTIE) | D36: 1323 | E36: 3318 | F36: 8225 | G36: 10878 | J36: 12917 | K36: 15118 | L36: 16572 | M36: 18443 | N36: 20432 | Q36: 21444 | R36: 24162 | S36: 27591 | T36: 30996 | U36: 33944 | X36: 34912 | Y36: 37568 | Z36: 39432 | AA36: 44970 | AB36: 49518 | AE36: 55274
A37: OBJECTIF | D37: 3262 | E37: =D37+3262 -> 6524 | F37: =E37+3262 -> 9786 | G37: =F37+3262 -> 13048 | J37: =G37+3262 -> 16310 | K37: =J37+3262 -> 19572 | L37: =K37+3262 -> 22834 | M37: =L37+3262 -> 26096 | N37: =M37+3262 -> 29358 | Q37: =N37+3262 -> 32620 | R37: =Q37+3262 -> 35882 | S37: =R37+3262 -> 39144 | T37: =S37+3262 -> 42406 | U37: =T37+3262 -> 45668 | X37: =U37+3262 -> 48930 | Y37: =X37+3262 -> 52192 | Z37: =Y37+3262 -> 55454 | AA37: =Z37+3262 -> 58716 | AB37: =AA37+3262 -> 61978 | AE37: =AB37+3262 -> 65240
A38: % DE REALISATION | D38: =D36/D37 -> 0.4055794 | E38: =E36/E37 -> 0.50858369 | F38: =F36/F37 -> 0.84048641 | G38: =G36/G37 -> 0.83369099 | J38: =J36/J37 -> 0.79196812 | K38: =K36/K37 -> 0.77243 | L38: =L36/L37 -> 0.72575983 | M38: =M36/M37 -> 0.70673666 | N38: =N36/N37 -> 0.69596022 | Q38: =Q36/Q37 -> 0.65738811 | R38: =R36/R37 -> 0.67337384 | S38: =S36/S37 -> 0.70485898 | T38: =T36/T37 -> 0.7309343 | U38: =U36/U37 -> 0.74327757 | X38: =X36/X37 -> 0.71350909 | Y38: =Y36/Y37 -> 0.7198038 | Z38: =Z36/Z37 -> 0.71107585 | AA38: =AA36/AA37 -> 0.76589005 | AB38: =AB36/AB37 -> 0.79896092 | AE38: =AE36/AE37 -> 0.84724096
A42: FORD PEROLS | B42: 1 | C42: 2 | D42: 3 | E42: 4 | F42: 5 | G42: 6 | H42: 7 | I42: 8 | J42: 9 | K42: 10 | L42: 11 | M42: 12 | N42: 13 | O42: 14 | P42: 15 | Q42: 16 | R42: 17 | S42: 18 | T42: 19 | U42: 20 | V42: 21 | W42: 22 | X42: 23 | Y42: 24 | Z42: 25 | AA42: 26 | AB42: 27 | AC42: 28 | AD42: 29 | AE42: 30
A43: CA REALISE (CLIENT CESSION GARANTIE) | D43: 0 | E43: 365 | F43: 1277 | G43: 1643 | J43: 1853 | K43: 1853 | L43: 1853 | M43: 1853 | N43: 1853 | Q43: 3490 | R43: 4488 | S43: 5599 | T43: 6742 | U43: 7030 | X43: 7810 | Y43: 8093 | Z43: 8597 | AA43: 9370 | AB43: 10322 | AE43: 10865
